Workbook

Sheet Categorías
B2: Índice de capacidad
B3: Institución | C3: Ponderación total | D3: Variables
B4: Organo Coordinación | C4: 0.15 | D4: Existencia (15%) | F4: Máx 100% | G4: Min 0%
B5: Poder Judicial | C5: 0.3 | D5: Capacidad instalada de tasa de operadores (7%) Variación tasa de operadores jueces penales (3%) Presupuesto instalado (7%) Variación presupuestal (3%) Carrera Judicial (5%) Salas (5%)
B6: Fiscalía | C6: 0.35 | D6: Capacidad instalada de tasa de operadores (7%) Variación tasa de operadores fiscales (3%) Presupuesto instalado (7%) Variación presupuestal (3%) Autonomía (5%) Modelo de Gestión; Asuntos Internos, MASC, UMECA, Atención esp. Mujeres y Adolescentes (5%, 1% c/u) Agencias (5%)
B7: Defensoría Pública | C7: 0.2 | D7: Capacidad instalada de tasa de operadores (7%) Variación tasa de operadores defensores (3%) Presupuesto instalado (7%) Variación presupuestal (3%)

Sheet Org Coord
A1: Índice de capacidad
H2: Fuente pública: Busquedas en google
A3: Entidades / Variable | B3: Institución identficada | C3: Reclasificado | D3: Total Org Coord | H3: Entidad | I3: Evidencia del 2023 o posterior | J3: Nombre | K3: Link | L3: Comentarios
A4: Federación | H4: Federación | I4: No | L4: Después de SETEC paso al SESNSP y luego SEGOB hizo una Unidad de Apoyo al Sistema de Justicia Penal, el Poder Judicial igual hizo una unidad, de las dos no queda nada reciente
A5: Aguascalientes | B5: No | C5: 0 | D5: =C5*0.25 -> 0 | H5: Aguascalientes | I5: No | J5: Órgano Implementador del Sistema de Justicia Penal en el Estado de Aguascalientes | K5: https://eservicios2.aguascalientes.gob.mx/NormatecaAdministrador/archivos/EDO-26-181.pdf | L5: Reglamento de 2018
A6: Baja California | B6: No | C6: 0 | D6: =C6*0.25 -> 0 | H6: Baja California | I6: Hallazgos 2023 | L6: Lo más parecido que encontré fue http://www.justiciabc.gob.mx/ que es prácticamente nada
A7: Baja California Sur | B7: Si | C7: 1 | D7: 0.15 | H7: Baja California Sur | I7: Si | J7: Secretaría Ejecutiva de la Comisión de Consolidación del SJP BCS | K7: https://justiciapenalbcs.gob.mx/#:~:text=La%20Comisi%C3%B3n%20de%20Consolidaci%C3%B3n%20del,Justicia%20Penal%20para%20el%20Estado. | L7: También tienen FB https://www.facebook.com/SJPBCS?ref=embed_page
A8: Campeche | B8: No | C8: 0 | D8: 0 | H8: Campeche | I8: No
A9: Coahuila de Zaragoza | B9: Si | C9: 1 | D9: 0.15 | H9: Coahuila de Zaragoza | I9: Si | J9: Comisión para la Instrumentación del Nuevo Sistema de Justicia Penal de Coahuila | K9: http://sistemapenalcoahuila.gob.mx/ | L9: Lo úlitmo que encontré es que sacaron unas cápsulas como de radio en 2024, pero realmente parece fantasma
A10: Colima | B10: No | C10: 0 | D10: =C10*0.25 -> 0 | H10: Colima | I10: Hallazgos 2023
A11: Chiapas | B11: No | C11: 0 | D11: =C11*0.25 -> 0 | H11: Chiapas | I11: Hallazgos 2023 | L11: UNODC 2022
A12: Chihuahua | B12: Si | C12: 1 | D12: 0.15 | H12: Chihuahua | I12: Si | J12: Centro Estatal para la Consolidación del Sistema de Justicia Penal | K12: https://www.facebook.com/conspen.stj/?locale=es_LA | L12: Es sólo del Poder Judicial
A13: Ciudad de México | B13: No | C13: 0 | D13: =C13*0.25 -> 0 | H13: Ciudad de México | I13: No | L13: UNODC 2022
A14: Durango | B14: No | C14: 0 | D14: =C14*0.25 -> 0 | H14: Durango | I14: Hallazgos 2023 | J14: Organismo Implementador de la Reforma Penal Durango | L14: Parece que murió en 2017
A15: Guanajuato | B15: Si | C15: 1 | D15: 0.15 | H15: Guanajuato | I15: Si | J15: Comisión Estatal para la Evaluación y Consolidación del Sistema de Justicia Penal | K15: https://boletines.guanajuato.gob.mx/2025/02/20/fortalecen-el-sistema-de-justicia-penal-en-el-estado-de-guanajuato/ | L15: Sabemos que hubo en 2023 y que rehicieron en 2025, no tiene página própia pero sacan boletines cada tantos años UNODC 2022
A16: Guerrero | B16: No | C16: 0 | D16: =C16*0.25 -> 0 | H16: Guerrero | I16: Hallazgos 2023
A17: Hidalgo | B17: No | C17: 0 | D17: =C17*0.25 -> 0 | H17: Hidalgo | I17: Hallazgos 2023
A18: Jalisco | B18: No | C18: 0 | D18: =C18*0.25 -> 0 | H18: Jalisco | I18: Hallazgos 2023
A19: México | B19: No | C19: 0 | D19: =C19*0.25 -> 0 | H19: México | I19: No | L19: Parece que crearon uno en 2024
A20: Michoacán de Ocampo | B20: No | C20: 0 | D20: =C20*0.25 -> 0 | H20: Michoacán de Ocampo | I20: Hallazgos 2023
A21: Morelos | B21: No | C21: 0 | D21: =C21*0.25 -> 0 | H21: Morelos | I21: No
A22: Nayarit | B22: No | C22: 0 | D22: =C22*0.25 -> 0 | H22: Nayarit | I22: No
A23: Nuevo León | B23: Si | C23: 1 | D23: 0.15 | H23: Nuevo León | I23: Si | J23: Comisión Ejecutiva para la Consolidación del Sistema de Justicia y Supervisión de Libertad Condicionada del Estado de Nuevo León | K23: https://www.facebook.com/sijupenl/?locale=es_LA
A24: Oaxaca | B24: No | C24: 0 | D24: =C24*0.25 -> 0 | H24: Oaxaca | I24: No
A25: Puebla | B25: No | C25: 0 | D25: =C25*0.25 -> 0 | H25: Puebla | I25: Hallazgos 2023 | J25: Comisión Ejecutiva para la Actualización y Modernización de la Procuración y Administración de Justicia | L25: Parece que hubo algo, pero no queda mucha evidencia
A26: Querétaro | B26: Si | C26: 1 | D26: 0.15 | H26: Querétaro | I26: Si | J26: Comisión Cosmos | K26: https://cosmos.gob.mx/sistema-cosmos#gsc.tab=0
A27: Quintana Roo | B27: No | C27: 0 | D27: =C27*0.25 -> 0 | H27: Quintana Roo | I27: No | L27: UNODC 2022
A28: San Luis Potosí | B28: No | C28: 0 | D28: =C28*0.25 -> 0 | H28: San Luis Potosí | I28: No | L28: UNODC 2022
A29: Sinaloa | B29: No | C29: 0 | D29: =C29*0.25 -> 0 | H29: Sinaloa | I29: Hallazgos 2023
A30: Sonora | B30: No | C30: 0 | D30: =C30*0.25 -> 0 | H30: Sonora | I30: Hallazgos 2023
A31: Tabasco | B31: No | C31: 0 | D31: =C31*0.25 -> 0 | H31: Tabasco | I31: Hallazgos 2023
A32: Tamaulipas | B32: No | C32: 0 | D32: =C32*0.25 -> 0 | H32: Tamaulipas | I32: Hallazgos 2023 | J32: Dirección para la Consolidación del Sistema de Justicia Penal | L32: No hay mucha evidencia de su existencia real
A33: Tlaxcala | B33: No | C33: 0 | D33: =C33*0.25 -> 0 | H33: Tlaxcala | I33: Hallazgos 2023
A34: Veracruz de Ignacio de la Llave | B34: No | C34: 0 | D34: =C34*0.25 -> 0 | H34: Veracruz de Ignacio de la Llave | I34: Hallazgos 2023
A35: Yucatán | B35: No | C35: 0 | D35: =C35*0.25 -> 0 | H35: Yucatán | I35: No | L35: UNODC 2022
A36: Zacatecas | B36: No | C36: 0 | D36: =C36*0.25 -> 0 | H36: Zacatecas | I36: No

Sheet Poder Judicial
A2: Fuente: | B2: Proyecciones CONAPO | C2: Proyecciones CONAPO | D2: INEGI. Censo Nacional de Impartición de Justicia Estatal 2023. Tabulados básicos Jueces en el Sistema Penal Acusatorio del Poder Judicial, por entidad federativa según función y sexo 2022 Suma de todos | E2: CNIJE 2024 Metadatos (Valeria) | I2: Sólo se puede hasta 0% y si no hay dato igual 0% y señalar con * que fue por falta de información si presetnamos los datos de un estado o de una institución | N2: INEGI. Censo Nacional de Impartición de Justicia Estatal 2023. Tabulados básicos Presupuesto ejercido por el Poder Judicial, por entidad federativa según capítulo del Clasificador por Objeto del Gasto 2022 Columna C | O2: INEGI Censo Nacional de Impartición de Justicia Estatal 2024. Tabulados básicos Presupuesto ejercido por el Poder Judicial estatal, por entidad federativa 2023 Columna C | U2: INEGI Censo Nacional de Impartición de Justicia Estatal 2024. Tabulados básicos Comisiones y/o comités del Poder Judicial, por nivel de gobierno y entidad federativa según tema o asunto principal 2023 Carrera Judicial (Columna N) | W2: CNIJE 2024 Metadatos (Valeria)
G3: Val max | H3: =MAX(G7:G38) -> 6.0537962 | J3: Val max | K3: =MAX(J7:J38) -> 0.85821704 | O3: Val max | P3: =MAX(O7:O38) -> 7.8694473e+09 | R3: Val max | S3: =MAX(R7:R38) -> 0.38239661 | X3: Val max | Y3: =MAX(X7:X38) -> 4.2069901
G4: Val min | H4: =MIN(G7:G38) -> 0.049514608 | I4: 0.07 | J4: Val min | K4: =MIN(J7:J38) -> -0.96084066 | L4: 0.03 | N4: Variación presupuestal (10%) | O4: Val min | P4: =MIN(O7:O38) -> 243159329 | Q4: 0.07 | R4: Val min | S4: =MIN(R7:R38) -> -0.22517562 | T4: 0.03 | V4: 0.05 | X4: Val min | Y4: =MIN(X7:X38) -> 0.34690158 | Z4: 0.05 | AB4: =I4+L4+Q4+T4+V4+Z4 -> 0.3
A5: Entidades / Variable | B5: Población 2022 | C5: Población 2023 | D5: Número de jueces en materia penal 2022 | E5: Número de jueces en materia penal 2023 | F5: Tasa de operadores 2022 | G5: Tasa de operadores 2023 | H5: Capacidad Jueces 2023 normal | I5: Capacidad instalada | J5: Variación TO Jueces | K5: Var TO Juez Normal | L5: Variación TO Jueces | M5: Suma personal | N5: Presupuesto ejercido 2022 | O5: Presupuesto ejercido 2023 | P5: Presupuesto instalado PJ normal | Q5: Presupuesto instalado PJ | R5: Variación Presup Pod Jud | S5: Var Pres PJ Normal | T5: Variación Presup Pod Jud | U5: Carrera judicial | V5: Comité de Carrera Judicial | W5: Salas 2023 | X5: Salas por 100,000 2023 | Y5: Salas por pob normal | Z5: Salas por 100,000 2023 | AB5: Total Poder Judicial
A6: Federación
A7: Aguascalientes | B7: 1491126 | C7: 1510839 | D7: 18 | E7: 18 | F7: =(D7/B7)*100000 -> 1.2071414 | G7: =(E7/C7)*100000 -> 1.191391 | H7: =(G7-$H$4)/($H$3-$H$4) -> 0.19017702 | I7: =(H7*I$14)/H$14 -> 0.013312392 | J7: =((G7-F7)/F7) -> -0.013047717 | K7: =(J7-$K$4)/($K$3-$K$4) -> 0.52103512 | L7: =(K7*$L$14)/$K$14 -> 0.015631054 | M7: =L7+I7 -> 0.028943445 | N7: 574436047 | O7: 642505717 | P7: =(O7-$P$4)/($P$3-$P$4) -> 0.052364452 | Q7: =(P7*$Q$15)/$P$15 -> 0.0036655116 | R7: =(O7-N7)/N7 -> 0.11849826 | S7: =(R7-$S$4)/($S$3-$S$4) -> 0.56565107 | T7: =(S7*$T$27)/$S$27 -> 0.016969532 | U7: 0 | V7: 0 | W7: 54 | X7: =(W7/B7)*100000 -> 3.6214243 | Y7: =(X7-$Y$4)/($Y$3-$Y$4) -> 0.84830251 | Z7: =(Y7*$Z$14)/$Y$14 -> 0.042415126 | AB7: =I7+L7+Q7+T7+V7+Z7 -> 0.091993614
A8: Baja California | B8: 3948201 | C8: 4010510 | D8: 55 | E8: 61 | F8: =D8/B8*100000 -> 1.3930395 | G8: =(E8/C8)*100000 -> 1.5210036 | H8: =(G8-$H$4)/($H$3-$H$4) -> 0.24507327 | I8: =(H8*I$14)/H$14 -> 0.017155129 | J8: =((G8-F8)/F8) -> 0.091859598 | K8: =(J8-$K$4)/($K$3-$K$4) -> 0.57870636 | L8: =(K8*$L$14)/$K$14 -> 0.017361191 | M8: =L8+I8 -> 0.03451632 | N8: 1296457311 | O8: 1769359358 | P8: =(O8-$P$4)/($P$3-$P$4) -> 0.20012358 | Q8: =(P8*$Q$15)/$P$15 -> 0.01400865 | R8: =(O8-N8)/N8 -> 0.36476484 | S8: =(R8-$S$4)/($S$3-$S$4) -> 0.97097997 | T8: =(S8*$T$27)/$S$27 -> 0.029129399 | U8: 1 | V8: 0.05 | W8: 41 | X8: =(W8/B8)*100000 -> 1.0384476 | Y8: =(X8-$Y$4)/($Y$3-$Y$4) -> 0.1791529 | Z8: =(Y8*$Z$14)/$Y$14 -> 0.0089576451 | AB8: =I8+L8+Q8+T8+V8+Z8 -> 0.13661201
A9: Baja California Sur | B9: 849224 | C9: 867766 | D9: 36 | E9: 21 | F9: =D9/B9*100000 -> 4.2391642 | G9: =(E9/C9)*100000 -> 2.4200072 | H9: =(G9-$H$4)/($H$3-$H$4) -> 0.39480038 | I9: =(H9*I$14)/H$14 -> 0.027636026 | J9: =((G9-F9)/F9) -> -0.42913105 | K9: =(J9-$K$4)/($K$3-$K$4) -> 0.29229948 | L9: =(K9*$L$14)/$K$14 -> 0.0087689843 | M9: =L9+I9 -> 0.036405011 | N9: 425218229 | O9: 471467668 | P9: =(O9-$P$4)/($P$3-$P$4) -> 0.029937021 | Q9: =(P9*$Q$15)/$P$15 -> 0.0020955914 | R9: =(O9-N9)/N9 -> 0.10876636 | S9: =(R9-$S$4)/($S$3-$S$4) -> 0.54963339 | T9: =(S9*$T$27)/$S$27 -> 0.016489002 | U9: 1 | V9: 0.05 | W9: 33 | X9: =(W9/B9)*100000 -> 3.8859005 | Y9: =(X9-$Y$4)/($Y$3-$Y$4) -> 0.91681809 | Z9: =(Y9*$Z$14)/$Y$14 -> 0.045840905 | AB9: =I9+L9+Q9+T9+V9+Z9 -> 0.15083051
A10: Campeche | B10: 945445 | C10: 950291 | D10: 9 | E10: 11 | F10: =D10/B10*100000 -> 0.95193269 | G10: =(E10/C10)*100000 -> 1.1575402 | H10: =(G10-$H$4)/($H$3-$H$4) -> 0.18453924 | I10: =(H10*I$14)/H$14 -> 0.012917747 | J10: =((G10-F10)/F10) -> 0.21598951 | K10: =(J10-$K$4)/($K$3-$K$4) -> 0.64694494 | L10: =(K10*$L$14)/$K$14 -> 0.019408348 | M10: =L10+I10 -> 0.032326095 | N10: 323626925 | O10: 326562636 | P10: =(O10-$P$4)/($P$3-$P$4) -> 0.010936291 | Q10: =(P10*$Q$15)/$P$15 -> 0.0007655404 | R10: =(O10-N10)/N10 -> 0.0090712817 | S10: =(R10-$S$4)/($S$3-$S$4) -> 0.38554577 | T10: =(S10*$T$27)/$S$27 -> 0.011566373 | U10: 1 | V10: 0.05 | W10: 35 | X10: =(W10/B10)*100000 -> 3.7019605 | Y10: =(X10-$Y$4)/($Y$3-$Y$4) -> 0.86916631 | Z10: =(Y10*$Z$14)/$Y$14 -> 0.043458316 | AB10: =I10+L10+Q10+T10+V10+Z10 -> 0.13811632
A11: Coahuila de Zaragoza | B11: 3273658 | C11: 3316738 | D11: 36 | E11: 36 | F11: =D11/B11*100000 -> 1.0996873 | G11: =(E11/C11)*100000 -> 1.0854038 | H11: =(G11-$H$4)/($H$3-$H$4) -> 0.17252508 | I11: =(H11*I$14)/H$14 -> 0.012076756 | J11: =((G11-F11)/F11) -> -0.012988665 | K11: =(J11-$K$4)/($K$3-$K$4) -> 0.52106758 | L11: =(K11*$L$14)/$K$14 -> 0.015632027 | M11: =L11+I11 -> 0.027708783 | N11: 1093452951 | O11: 1339981857 | P11: =(O11-$P$4)/($P$3-$P$4) -> 0.14382128 | Q11: =(P11*$Q$15)/$P$15 -> 0.01006749 | R11: =(O11-N11)/N11 -> 0.22545909 | S11: =(R11-$S$4)/($S$3-$S$4) -> 0.74169735 | T11: =(S11*$T$27)/$S$27 -> 0.02225092 | U11: 0 | V11: 0 | W11: 73 | X11: =(W11/B11)*100000 -> 2.2299214 | Y11: =(X11-$Y$4)/($Y$3-$Y$4) -> 0.48781778 | Z11: =(Y11*$Z$14)/$Y$14 -> 0.024390889 | AB11: =I11+L11+Q11+T11+V11+Z11 -> 0.084418083
A12: Colima | B12: 752247 | C12: 757405 | D12: 12 | E12: 1 | F12: =D12/B12*100000 -> 1.5952207 | G12: =(E12/C12)*100000 -> 0.13202976 | H12: =(G12-$H$4)/($H$3-$H$4) -> 0.013742718 | I12: =(H12*I$14)/H$14 -> 0.00096199029 | J12: =((G12-F12)/F12) -> -0.91723417 | K12: =(J12-$K$4)/($K$3-$K$4) -> 0.023972018 | L12: =(K12*$L$14)/$K$14 -> 0.00071916055 | M12: =L12+I12 -> 0.0016811508 | N12: 275607350 | O12: 243159329 | P12: =(O12-$P$4)/($P$3-$P$4) -> 0 | Q12: =(P12*$Q$15)/$P$15 -> 0 | R12: =(O12-N12)/N12 -> -0.11773279 | S12: =(R12-$S$4)/($S$3-$S$4) -> 0.17683961 | T12: =(S12*$T$27)/$S$27 -> 0.0053051884 | U12: 0 | V12: 0 | W12: 18 | X12: =(W12/B12)*100000 -> 2.3928311 | Y12: =(X12-$Y$4)/($Y$3-$Y$4) -> 0.5300214 | Z12: =(Y12*$Z$14)/$Y$14 -> 0.02650107 | AB12: =I12+L12+Q12+T12+V12+Z12 -> 0.033487409
A13: Chiapas | B13: 5862882 | C13: 5946352 | D13: 25 | E13: 34 | F13: =D13/B13*100000 -> 0.42641145 | G13: =(E13/C13)*100000 -> 0.57177913 | H13: =(G13-$H$4)/($H$3-$H$4) -> 0.086982017 | I13: =(H13*I$14)/H$14 -> 0.0060887412 | J13: =((G13-F13)/F13) -> 0.34090944 | K13: =(J13-$K$4)/($K$3-$K$4) -> 0.71561782 | L13: =(K13*$L$14)/$K$14 -> 0.021468535 | M13: =L13+I13 -> 0.027557276 | N13: 1110214762 | O13: 1223152165 | P13: =(O13-$P$4)/($P$3-$P$4) -> 0.12850195 | Q13: =(P13*$Q$15)/$P$15 -> 0.0089951362 | R13: =(O13-N13)/N13 -> 0.10172573 | S13: =(R13-$S$4)/($S$3-$S$4) -> 0.53804525 | T13: =(S13*$T$27)/$S$27 -> 0.016141357 | U13: 1 | V13: 0.05 | W13: 41 | X13: =(W13/B13)*100000 -> 0.69931477 | Y13: =(X13-$Y$4)/($Y$3-$Y$4) -> 0.091296662 | Z13: =(Y13*$Z$14)/$Y$14 -> 0.0045648331 | AB13: =I13+L13+Q13+T13+V13+Z13 -> 0.1072586
A14: Chihuahua | B14: 3898274 | C14: 3947936 | D14: 127 | E14: 239 | F14: =D14/B14*100000 -> 3.2578521 | G14: =(E14/C14)*100000 -> 6.0537962 | H14: =(G14-$H$4)/($H$3-$H$4) -> 1 | I14: 0.07 | J14: =((G14-F14)/F14) -> 0.85821704 | K14: =(J14-$K$4)/($K$3-$K$4) -> 1 | L14: 0.03 | M14: =L14+I14 -> 0.1 | N14: 2938124694 | O14: 3004866458 | P14: =(O14-$P$4)/($P$3-$P$4) -> 0.36212993 | Q14: =(P14*$Q$15)/$P$15 -> 0.025349095 | R14: =(O14-N14)/N14 -> 0.02271577 | S14: =(R14-$S$4)/($S$3-$S$4) -> 0.40800317 | T14: =(S14*$T$27)/$S$27 -> 0.012240095 | U14: 1 | V14: 0.05 | W14: 164 | X14: =(W14/B14)*100000 -> 4.2069901 | Y14: =(X14-$Y$4)/($Y$3-$Y$4) -> 1 | Z14: 0.05 | AB14: =I14+L14+Q14+T14+V14+Z14 -> 0.23758919
A15: Ciudad de México | B15: 9237644 | C15: 9221637 | D15: 152 | E15: 150 | F15: =D15/B15*100000 -> 1.6454412 | G15: =(E15/C15)*100000 -> 1.6266092 | H15: =(G15-$H$4)/($H$3-$H$4) -> 0.26266167 | I15: =(H15*I$14)/H$14 -> 0.018386317 | J15: =((G15-F15)/F15) -> -0.011444925 | K15: =(J15-$K$4)/($K$3-$K$4) -> 0.52191623 | L15: =(K15*$L$14)/$K$14 -> 0.015657487 | M15: =L15+I15 -> 0.034043804 | N15: 7.3812036e+09 | O15: 7.8694473e+09 | P15: =(O15-$P$4)/($P$3-$P$4) -> 1 | Q15: 0.07 | R15: =(O15-N15)/N15 -> 0.066146896 | S15: =(R15-$S$4)/($S$3-$S$4) -> 0.47948623 | T15: =(S15*$T$27)/$S$27 -> 0.014384587 | U15: 1 | V15: 0.05 | W15: 207 | X15: =(W15/B15)*100000 -> 2.2408311 | Y15: =(X15-$Y$4)/($Y$3-$Y$4) -> 0.49064407 | Z15: =(Y15*$Z$14)/$Y$14 -> 0.024532203 | AB15: =I15+L15+Q15+T15+V15+Z15 -> 0.19296059
A16: Durango | B16: 1884286 | C16: 1899457 | D16: 45 | E16: 37 | F16: =D16/B16*100000 -> 2.3881725 | G16: =(E16/C16)*100000 -> 1.9479251 | H16: =(G16-$H$4)/($H$3-$H$4) -> 0.31617613 | I16: =(H16*I$14)/H$14 -> 0.022132329 | J16: =((G16-F16)/F16) -> -0.18434488 | K16: =(J16-$K$4)/($K$3-$K$4) -> 0.42686704 | L16: =(K16*$L$14)/$K$14 -> 0.012806011 | M16: =L16+I16 -> 0.03493834 | N16: 512774756 | O16: 506276160 | P16: =(O16-$P$4)/($P$3-$P$4) -> 0.034501298 | Q16: =(P16*$Q$15)/$P$15 -> 0.0024150908 | R16: =(O16-N16)/N16 -> -0.012673393 | S16: =(R16-$S$4)/($S$3-$S$4) -> 0.34975633 | T16: =(S16*$T$27)/$S$27 -> 0.01049269 | U16: 1 | V16: 0.05 | W16: 36 | X16: =(W16/B16)*100000 -> 1.910538 | Y16: =(X16-$Y$4)/($Y$3-$Y$4) -> 0.40507787 | Z16: =(Y16*$Z$14)/$Y$14 -> 0.020253893 | AB16: =I16+L16+Q16+T16+V16+Z16 -> 0.11810001
A17: Guanajuato | B17: 6360814 | C17: 6422483 | D17: 77 | E17: 77 | F17: =D17/B17*100000 -> 1.2105369 | G17: =(E17/C17)*100000 -> 1.1989133 | H17: =(G17-$H$4)/($H$3-$H$4) -> 0.19142984 | I17: =(H17*I$14)/H$14 -> 0.013400089 | J17: =((G17-F17)/F17) -> -0.0096020495 | K17: =(J17-$K$4)/($K$3-$K$4) -> 0.52292932 | L17: =(K17*$L$14)/$K$14 -> 0.01568788 | M17: =L17+I17 -> 0.029087968 | N17: 1935937925 | O17: 2157580161 | P17: =(O17-$P$4)/($P$3-$P$4) -> 0.25102918 | Q17: =(P17*$Q$15)/$P$15 -> 0.017572043 | R17: =(O17-N17)/N17 -> 0.1144883 | S17: =(R17-$S$4)/($S$3-$S$4) -> 0.55905109 | T17: =(S17*$T$27)/$S$27 -> 0.016771533 | U17: 0 | V17: 0 | W17: 157 | X17: =(W17/B17)*100000 -> 2.4682376 | Y17: =(X17-$Y$4)/($Y$3-$Y$4) -> 0.54955631 | Z17: =(Y17*$Z$14)/$Y$14 -> 0.027477815 | AB17: =I17+L17+Q17+T17+V17+Z17 -> 0.090909359
A18: Guerrero | B18: 3599951 | C18: 3604215 | D18: 32 | E18: 31 | F18: =D18/B18*100000 -> 0.88890099 | G18: =(E18/C18)*100000 -> 0.86010407 | H18: =(G18-$H$4)/($H$3-$H$4) -> 0.13500191 | I18: =(H18*I$14)/H$14 -> 0.0094501335 | J18: =((G18-F18)/F18) -> -0.032396089 | K18: =(J18-$K$4)/($K$3-$K$4) -> 0.51039864 | L18: =(K18*$L$14)/$K$14 -> 0.015311959 | M18: =L18+I18 -> 0.024762093 | N18: 969645223 | O18: 1003374663 | P18: =(O18-$P$4)/($P$3-$P$4) -> 0.099683534 | Q18: =(P18*$Q$15)/$P$15 -> 0.0069778474 | R18: =(O18-N18)/N18 -> 0.034785341 | S18: =(R18-$S$4)/($S$3-$S$4) -> 0.42786841 | T18: =(S18*$T$27)/$S$27 -> 0.012836052 | U18: 0 | V18: 0 | W18: 31 | X18: =(W18/B18)*100000 -> 0.86112283 | Y18: =(X18-$Y$4)/($Y$3-$Y$4) -> 0.13321489 | Z18: =(Y18*$Z$14)/$Y$14 -> 0.0066607444 | AB18: =I18+L18+Q18+T18+V18+Z18 -> 0.051236737
A19: Hidalgo | B19: 3190331 | C19: 3227801 | D19: 50 | E19: 53 | F19: =D19/B19*100000 -> 1.5672355 | G19: =(E19/C19)*100000 -> 1.6419847 | H19: =(G19-$H$4)/($H$3-$H$4) -> 0.26522243 | I19: =(H19*I$14)/H$14 -> 0.01856557 | J19: =((G19-F19)/F19) -> 0.047694966 | K19: =(J19-$K$4)/($K$3-$K$4) -> 0.55442751 | L19: =(K19*$L$14)/$K$14 -> 0.016632825 | M19: =L19+I19 -> 0.035198395 | N19: 588774113 | O19: 644961751 | P19: =(O19-$P$4)/($P$3-$P$4) -> 0.0526865 | Q19: =(P19*$Q$15)/$P$15 -> 0.003688055 | R19: =(O19-N19)/N19 -> 0.09543157 | S19: =(R19-$S$4)/($S$3-$S$4) -> 0.52768573 | T19: =(S19*$T$27)/$S$27 -> 0.015830572 | U19: 1 | V19: 0.05 | W19: 52 | X19: =(W19/B19)*100000 -> 1.6299249 | Y19: =(X19-$Y$4)/($Y$3-$Y$4) -> 0.33238185 | Z19: =(Y19*$Z$14)/$Y$14 -> 0.016619092 | AB19: =I19+L19+Q19+T19+V19+Z19 -> 0.12133611
A20: Jalisco | B20: 8647986 | C20: 8735511 | D20: 321 | E20: 35 | F20: =D20/B20*100000 -> 3.7118469 | G20: =(E20/C20)*100000 -> 0.40066345 | H20: =(G20-$H$4)/($H$3-$H$4) -> 0.058483074 | I20: =(H20*I$14)/H$14 -> 0.0040938152 | J20: =((G20-F20)/F20) -> -0.8920582 | K20: =(J20-$K$4)/($K$3-$K$4) -> 0.03781214 | L20: =(K20*$L$14)/$K$14 -> 0.0011343642 | M20: =L20+I20 -> 0.0052281794 | N20: 2028821875 | O20: 2112632365 | P20: =(O20-$P$4)/($P$3-$P$4) -> 0.24513539 | Q20: =(P20*$Q$15)/$P$15 -> 0.017159477 | R20: =(O20-N20)/N20 -> 0.04130993 | S20: =(R20-$S$4)/($S$3-$S$4) -> 0.4386072 | T20: =(S20*$T$27)/$S$27 -> 0.013158216 | U20: 4 | V20: 0.05 | W20: 30 | X20: =(W20/B20)*100000 -> 0.34690158 | Y20: =(X20-$Y$4)/($Y$3-$Y$4) -> 0 | Z20: =(Y20*$Z$14)/$Y$14 -> 0 | AB20: =I20+L20+Q20+T20+V20+Z20 -> 0.085545872
A21: México | B21: 17379644 | C21: 17501220 | D21: 200 | E21: 206 | F21: =D21/B21*100000 -> 1.1507716 | G21: =(E21/C21)*100000 -> 1.1770608 | H21: =(G21-$H$4)/($H$3-$H$4) -> 0.18779036 | I21: =(H21*I$14)/H$14 -> 0.013145325 | J21: =((G21-F21)/F21) -> 0.022844883 | K21: =(J21-$K$4)/($K$3-$K$4) -> 0.54076654 | L21: =(K21*$L$14)/$K$14 -> 0.016222996 | M21: =L21+I21 -> 0.029368321 | N21: 5.5041894e+09 | O21: 5653896363 | P21: =(O21-$P$4)/($P$3-$P$4) -> 0.70948502 | Q21: =(P21*$Q$15)/$P$15 -> 0.049663951 | R21: =(O21-N21)/N21 -> 0.027198729 | S21: =(R21-$S$4)/($S$3-$S$4) -> 0.41538164 | T21: =(S21*$T$27)/$S$27 -> 0.012461449 | U21: 0 | V21: 0 | W21: 281 | X21: =(W21/B21)*100000 -> 1.616834 | Y21: =(X21-$Y$4)/($Y$3-$Y$4) -> 0.3289905 | Z21: =(Y21*$Z$14)/$Y$14 -> 0.016449525 | AB21: =I21+L21+Q21+T21+V21+Z21 -> 0.10794325
A22: Michoacán de Ocampo | B22: 4901506 | C22: 4950601 | D22: 38 | E22: 43 | F22: =D22/B22*100000 -> 0.77527193 | G22: =(E22/C22)*100000 -> 0.86858141 | H22: =(G22-$H$4)/($H$3-$H$4) -> 0.13641379 | I22: =(H22*I$14)/H$14 -> 0.0095489652 | J22: =((G22-F22)/F22) -> 0.1203571 | K22: =(J22-$K$4)/($K$3-$K$4) -> 0.59437244 | L22: =(K22*$L$14)/$K$14 -> 0.017831173 | M22: =L22+I22 -> 0.027380138 | N22: 1516841830 | O22: 1577398458 | P22: =(O22-$P$4)/($P$3-$P$4) -> 0.17495263 | Q22: =(P22*$Q$15)/$P$15 -> 0.012246684 | R22: =(O22-N22)/N22 -> 0.039922836 | S22: =(R22-$S$4)/($S$3-$S$4) -> 0.43632419 | T22: =(S22*$T$27)/$S$27 -> 0.013089726 | U22: 1 | V22: 0.05 | W22: 32 | X22: =(W22/B22)*100000 -> 0.65286057 | Y22: =(X22-$Y$4)/($Y$3-$Y$4) -> 0.07926217 | Z22: =(Y22*$Z$14)/$Y$14 -> 0.0039631085 | AB22: =I22+L22+Q22+T22+V22+Z22 -> 0.10667966
A23: Morelos | B23: 2017078 | C23: 2030857 | D23: 25 | E23: 23 | F23: =D23/B23*100000 -> 1.2394166 | G23: =(E23/C23)*100000 -> 1.1325268 | H23: =(G23-$H$4)/($H$3-$H$4) -> 0.18037332 | I23: =(H23*I$14)/H$14 -> 0.012626132 | J23: =((G23-F23)/F23) -> -0.086242035 | K23: =(J23-$K$4)/($K$3-$K$4) -> 0.48079763 | L23: =(K23*$L$14)/$K$14 -> 0.014423929 | M23: =L23+I23 -> 0.027050061 | N23: 803327279 | O23: 947016273 | P23: =(O23-$P$4)/($P$3-$P$4) -> 0.092293518 | Q23: =(P23*$Q$15)/$P$15 -> 0.0064605463 | R23: =(O23-N23)/N23 -> 0.17886732 | S23: =(R23-$S$4)/($S$3-$S$4) -> 0.66501219 | T23: =(S23*$T$27)/$S$27 -> 0.019950366 | U23: 0 | V23: 0 | W23: 26 | X23: =(W23/B23)*100000 -> 1.2889933 | Y23: =(X23-$Y$4)/($Y$3-$Y$4) -> 0.24405961 | Z23: =(Y23*$Z$14)/$Y$14 -> 0.012202981 | AB23: =I23+L23+Q23+T23+V23+Z23 -> 0.065663954
A24: Nayarit | B24: 1278605 | C24: 1294124 | D24: 21 | E24: 29 | F24: =D24/B24*100000 -> 1.642415 | G24: =(E24/C24)*100000 -> 2.2408981 | H24: =(G24-$H$4)/($H$3-$H$4) -> 0.36497014 | I24: =(H24*I$14)/H$14 -> 0.02554791 | J24: =((G24-F24)/F24) -> 0.36439214 | K24: =(J24-$K$4)/($K$3-$K$4) -> 0.72852709 | L24: =(K24*$L$14)/$K$14 -> 0.021855813 | M24: =L24+I24 -> 0.047403722 | N24: 555336510 | O24: 593946924 | P24: =(O24-$P$4)/($P$3-$P$4) -> 0.045997161 | Q24: =(P24*$Q$15)/$P$15 -> 0.0032198013 | R24: =(O24-N24)/N24 -> 0.069526158 | S24: =(R24-$S$4)/($S$3-$S$4) -> 0.48504814 | T24: =(S24*$T$27)/$S$27 -> 0.014551444 | U24: 1 | V24: 0.05 | W24: 21 | X24: =(W24/B24)*100000 -> 1.642415 | Y24: =(X24-$Y$4)/($Y$3-$Y$4) -> 0.33561754 | Z24: =(Y24*$Z$14)/$Y$14 -> 0.016780877 | AB24: =I24+L24+Q24+T24+V24+Z24 -> 0.13195584
A25: Nuevo León | B25: 6095498 | C25: 6202153 | D25: N/A | E25: 48 | F25: =D25/B25*100000 -> #VALUE! | G25: =(E25/C25)*100000 -> 0.7739248 | H25: =(G25-$H$4)/($H$3-$H$4) -> 0.12064894 | I25: =(H25*I$14)/H$14 -> 0.0084454255 | K25: N/A | L25: 0 | M25: =L25+I25 -> 0.0084454255 | N25: 2735111007 | O25: 2917680886 | P25: =(O25-$P$4)/($P$3-$P$4) -> 0.35069769 | Q25: =(P25*$Q$15)/$P$15 -> 0.024548838 | R25: =(O25-N25)/N25 -> 0.066750446 | S25: =(R25-$S$4)/($S$3-$S$4) -> 0.48047961 | T25: =(S25*$T$27)/$S$27 -> 0.014414388 | U25: 1 | V25: 0.05 | W25: 68 | X25: =(W25/B25)*100000 -> 1.1155774 | Y25: =(X25-$Y$4)/($Y$3-$Y$4) -> 0.19913426 | Z25: =(Y25*$Z$14)/$Y$14 -> 0.0099567128 | AB25: =I25+L25+Q25+T25+V25+Z25 -> 0.10736536
A26: Oaxaca | B26: 4244538 | C26: 4276769 | D26: 76 | E26: 66 | F26: =D26/B26*100000 -> 1.7905364 | G26: =(E26/C26)*100000 -> 1.5432211 | H26: =(G26-$H$4)/($H$3-$H$4) -> 0.24877355 | I26: =(H26*I$14)/H$14 -> 0.017414149 | J26: =((G26-F26)/F26) -> -0.13812363 | K26: =(J26-$K$4)/($K$3-$K$4) -> 0.45227649 | L26: =(K26*$L$14)/$K$14 -> 0.013568295 | M26: =L26+I26 -> 0.030982443 | N26: 1108050783 | O26: 1137137477 | P26: =(O26-$P$4)/($P$3-$P$4) -> 0.11722324 | Q26: =(P26*$Q$15)/$P$15 -> 0.0082056265 | R26: =(O26-N26)/N26 -> 0.026250326 | S26: =(R26-$S$4)/($S$3-$S$4) -> 0.41382067 | T26: =(S26*$T$27)/$S$27 -> 0.01241462 | U26: 1 | V26: 0.05 | W26: 62 | X26: =(W26/B26)*100000 -> 1.4607008 | Y26: =(X26-$Y$4)/($Y$3-$Y$4) -> 0.2885424 | Z26: =(Y26*$Z$14)/$Y$14 -> 0.01442712 | AB26: =I26+L26+Q26+T26+V26+Z26 -> 0.11602981
A27: Puebla | B27: 6824785 | C27: 6907421 | D27: 27 | E27: 27 | F27: =D27/B27*100000 -> 0.39561686 | G27: =(E27/C27)*100000 -> 0.39088395 | H27: =(G27-$H$4)/($H$3-$H$4) -> 0.056854319 | I27: =(H27*I$14)/H$14 -> 0.0039798023 | J27: =((G27-F27)/F27) -> -0.011963365 | K27: =(J27-$K$4)/($K$3-$K$4) -> 0.52163122 | L27: =(K27*$L$14)/$K$14 -> 0.015648937 | M27: =L27+I27 -> 0.019628739 | N27: 990338628 | O27: 1369040759 | P27: =(O27-$P$4)/($P$3-$P$4) -> 0.14763164 | Q27: =(P27*$Q$15)/$P$15 -> 0.010334215 | R27: =(O27-N27)/N27 -> 0.38239661 | S27: =(R27-$S$4)/($S$3-$S$4) -> 1 | T27: 0.03 | U27: 0 | V27: 0 | W27: 50 | X27: =(W27/B27)*100000 -> 0.73262381 | Y27: =(X27-$Y$4)/($Y$3-$Y$4) -> 0.099925749 | Z27: =(Y27*$Z$14)/$Y$14 -> 0.0049962874 | AB27: =I27+L27+Q27+T27+V27+Z27 -> 0.064959242
A28: Querétaro | B28: 2508214 | C28: 2557915 | D28: 16 | E28: 20 | F28: =D28/B28*100000 -> 0.6379041 | G28: =(E28/C28)*100000 -> 0.78188681 | H28: =(G28-$H$4)/($H$3-$H$4) -> 0.12197499 | I28: =(H28*I$14)/H$14 -> 0.0085382495 | J28: =((G28-F28)/F28) -> 0.22571215 | K28: =(J28-$K$4)/($K$3-$K$4) -> 0.65228982 | L28: =(K28*$L$14)/$K$14 -> 0.019568695 | M28: =L28+I28 -> 0.028106944 | N28: 1153600662 | O28: 1448406813 | P28: =(O28-$P$4)/($P$3-$P$4) -> 0.15803855 | Q28: =(P28*$Q$15)/$P$15 -> 0.011062698 | R28: =(O28-N28)/N28 -> 0.25555304 | S28: =(R28-$S$4)/($S$3-$S$4) -> 0.79122882 | T28: =(S28*$T$27)/$S$27 -> 0.023736865 | U28: 1 | V28: 0.05 | W28: 48 | X28: =(W28/B28)*100000 -> 1.9137123 | Y28: =(X28-$Y$4)/($Y$3-$Y$4) -> 0.40590021 | Z28: =(Y28*$Z$14)/$Y$14 -> 0.02029501 | AB28: =I28+L28+Q28+T28+V28+Z28 -> 0.13320152
A29: Quintana Roo | B29: 1977161 | C29: 2019606 | D29: 25 | E29: 1 | F29: =D29/B29*100000 -> 1.2644393 | G29: =(E29/C29)*100000 -> 0.049514608 | H29: =(G29-$H$4)/($H$3-$H$4) -> 0 | I29: =(H29*I$14)/H$14 -> 0 | J29: =((G29-F29)/F29) -> -0.96084066 | K29: =(J29-$K$4)/($K$3-$K$4) -> 0 | L29: =(K29*$L$14)/$K$14 -> 0 | M29: =L29+I29 -> 0 | N29: 764659335 | O29: 839092530 | P29: =(O29-$P$4)/($P$3-$P$4) -> 0.078141975 | Q29: =(P29*$Q$15)/$P$15 -> 0.0054699383 | R29: =(O29-N29)/N29 -> 0.097341642 | S29: =(R29-$S$4)/($S$3-$S$4) -> 0.5308295 | T29: =(S29*$T$27)/$S$27 -> 0.015924885 | U29: 0 | V29: 0 | W29: 52 | X29: =(W29/B29)*100000 -> 2.6300337 | Y29: =(X29-$Y$4)/($Y$3-$Y$4) -> 0.59147144 | Z29: =(Y29*$Z$14)/$Y$14 -> 0.029573572 | AB29: =I29+L29+Q29+T29+V29+Z29 -> 0.050968395
A30: San Luis Potosí | B30: 2905759 | C30: 2931052 | D30: 20 | E30: 19 | F30: =D30/B30*100000 -> 0.68828833 | G30: =(E30/C30)*100000 -> 0.64823142 | H30: =(G30-$H$4)/($H$3-$H$4) -> 0.099714979 | I30: =(H30*I$14)/H$14 -> 0.0069800485 | J30: =((G30-F30)/F30) -> -0.058197859 | K30: =(J30-$K$4)/($K$3-$K$4) -> 0.4962145 | L30: =(K30*$L$14)/$K$14 -> 0.014886435 | M30: =L30+I30 -> 0.021866483 | N30: 1321503084 | O30: 1316213153 | P30: =(O30-$P$4)/($P$3-$P$4) -> 0.1407046 | Q30: =(P30*$Q$15)/$P$15 -> 0.0098493223 | R30: =(O30-N30)/N30 -> -0.0040029653 | S30: =(R30-$S$4)/($S$3-$S$4) -> 0.36402694 | T30: =(S30*$T$27)/$S$27 -> 0.010920808 | U30: 1 | V30: 0.05 | W30: 24 | X30: =(W30/B30)*100000 -> 0.82594599 | Y30: =(X30-$Y$4)/($Y$3-$Y$4) -> 0.12410193 | Z30: =(Y30*$Z$14)/$Y$14 -> 0.0062050963 | AB30: =I30+L30+Q30+T30+V30+Z30 -> 0.09884171
A31: Sinaloa | B31: 3118470 | C31: 3142699 | D31: 25 | E31: 31 | F31: =D31/B31*100000 -> 0.80167518 | G31: =(E31/C31)*100000 -> 0.98641327 | H31: =(G31-$H$4)/($H$3-$H$4) -> 0.15603843 | I31: =(H31*I$14)/H$14 -> 0.01092269 | J31: =((G31-F31)/F31) -> 0.23044008 | K31: =(J31-$K$4)/($K$3-$K$4) -> 0.65488892 | L31: =(K31*$L$14)/$K$14 -> 0.019646668 | M31: =L31+I31 -> 0.030569358 | N31: 793626698 | O31: 834563127 | P31: =(O31-$P$4)/($P$3-$P$4) -> 0.077548055 | Q31: =(P31*$Q$15)/$P$15 -> 0.0054283639 | R31: =(O31-N31)/N31 -> 0.051581467 | S31: =(R31-$S$4)/($S$3-$S$4) -> 0.45551307 | T31: =(S31*$T$27)/$S$27 -> 0.013665392 | U31: 0 | V31: 0 | W31: 30 | X31: =(W31/B31)*100000 -> 0.96201022 | Y31: =(X31-$Y$4)/($Y$3-$Y$4) -> 0.15935092 | Z31: =(Y31*$Z$14)/$Y$14 -> 0.0079675458 | AB31: =I31+L31+Q31+T31+V31+Z31 -> 0.057630659
A32: Sonora | B32: 3051188 | C32: 3081734 | D32: 40 | E32: 40 | F32: =D32/B32*100000 -> 1.3109648 | G32: =(E32/C32)*100000 -> 1.2979706 | H32: =(G32-$H$4)/($H$3-$H$4) -> 0.20792761 | I32: =(H32*I$14)/H$14 -> 0.014554933 | J32: =((G32-F32)/F32) -> -0.0099119522 | K32: =(J32-$K$4)/($K$3-$K$4) -> 0.52275896 | L32: =(K32*$L$14)/$K$14 -> 0.015682769 | M32: =L32+I32 -> 0.030237702 | N32: 1477737885 | O32: 1631430220 | P32: =(O32-$P$4)/($P$3-$P$4) -> 0.18203757 | Q32: =(P32*$Q$15)/$P$15 -> 0.01274263 | R32: =(O32-N32)/N32 -> 0.10400514 | S32: =(R32-$S$4)/($S$3-$S$4) -> 0.54179692 | T32: =(S32*$T$27)/$S$27 -> 0.016253908 | U32: 1 | V32: 0.05 | W32: 40 | X32: =(W32/B32)*100000 -> 1.3109648 | Y32: =(X32-$Y$4)/($Y$3-$Y$4) -> 0.24975158 | Z32: =(Y32*$Z$14)/$Y$14 -> 0.012487579 | AB32: =I32+L32+Q32+T32+V32+Z32 -> 0.12172182
A33: Tabasco | B33: 2447193 | C33: 2454787 | D33: 48 | E33: 50 | F33: =D33/B33*100000 -> 1.9614309 | G33: =(E33/C33)*100000 -> 2.0368366 | H33: =(G33-$H$4)/($H$3-$H$4) -> 0.33098414 | I33: =(H33*I$14)/H$14 -> 0.02316889 | J33: =((G33-F33)/F33) -> 0.038444221 | K33: =(J33-$K$4)/($K$3-$K$4) -> 0.54934205 | L33: =(K33*$L$14)/$K$14 -> 0.016480261 | M33: =L33+I33 -> 0.039649151 | N33: 896431214 | O33: 914628744 | P33: =(O33-$P$4)/($P$3-$P$4) -> 0.088046691 | Q33: =(P33*$Q$15)/$P$15 -> 0.0061632684 | R33: =(O33-N33)/N33 -> 0.020299974 | S33: =(R33-$S$4)/($S$3-$S$4) -> 0.40402702 | T33: =(S33*$T$27)/$S$27 -> 0.012120811 | U33: 0 | V33: 0 | W33: 47 | X33: =(W33/B33)*100000 -> 1.9205678 | Y33: =(X33-$Y$4)/($Y$3-$Y$4) -> 0.4076762 | Z33: =(Y33*$Z$14)/$Y$14 -> 0.02038381 | AB33: =I33+L33+Q33+T33+V33+Z33 -> 0.07831704
A34: Tamaulipas | B34: 3652671 | C34: 3685588 | D34: 31 | E34: 36 | F34: =D34/B34*100000 -> 0.84869401 | G34: =(E34/C34)*100000 -> 0.97677765 | H34: =(G34-$H$4)/($H$3-$H$4) -> 0.15443364 | I34: =(H34*I$14)/H$14 -> 0.010810355 | J34: =((G34-F34)/F34) -> 0.15091852 | K34: =(J34-$K$4)/($K$3-$K$4) -> 0.61117313 | L34: =(K34*$L$14)/$K$14 -> 0.018335194 | M34: =L34+I34 -> 0.029145548 | N34: 1279808654 | O34: 991626942 | P34: =(O34-$P$4)/($P$3-$P$4) -> 0.09814311 | Q34: =(P34*$Q$15)/$P$15 -> 0.0068700177 | R34: =(O34-N34)/N34 -> -0.22517562 | S34: =(R34-$S$4)/($S$3-$S$4) -> 0 | T34: =(S34*$T$27)/$S$27 -> 0 | U34: 2 | V34: 0.05 | W34: 51 | X34: =(W34/B34)*100000 -> 1.3962385 | Y34: =(X34-$Y$4)/($Y$3-$Y$4) -> 0.27184272 | Z34: =(Y34*$Z$14)/$Y$14 -> 0.013592136 | AB34: =I34+L34+Q34+T34+V34+Z34 -> 0.099607702
A35: Tlaxcala | B35: 1395020 | C35: 1412895 | D35: 22 | E35: 22 | F35: =D35/B35*100000 -> 1.5770383 | G35: =(E35/C35)*100000 -> 1.5570867 | H35: =(G35-$H$4)/($H$3-$H$4) -> 0.25108284 | I35: =(H35*I$14)/H$14 -> 0.017575799 | J35: =((G35-F35)/F35) -> -0.012651329 | K35: =(J35-$K$4)/($K$3-$K$4) -> 0.52125303 | L35: =(K35*$L$14)/$K$14 -> 0.015637591 | M35: =L35+I35 -> 0.03321339 | N35: 443193425 | O35: 480464681 | P35: =(O35-$P$4)/($P$3-$P$4) -> 0.031116757 | Q35: =(P35*$Q$15)/$P$15 -> 0.002178173 | R35: =(O35-N35)/N35 -> 0.084097042 | S35: =(R35-$S$4)/($S$3-$S$4) -> 0.50903028 | T35: =(S35*$T$27)/$S$27 -> 0.015270909 | U35: 1 | V35: 0.05 | W35: 9 | X35: =(W35/B35)*100000 -> 0.64515204 | Y35: =(X35-$Y$4)/($Y$3-$Y$4) -> 0.077265188 | Z35: =(Y35*$Z$14)/$Y$14 -> 0.0038632594 | AB35: =I35+L35+Q35+T35+V35+Z35 -> 0.10452573
A36: Veracruz de Ignacio de la Llave | B36: 8133233 | C36: 8131584 | D36: 67 | E36: 70 | F36: =D36/B36*100000 -> 0.82378065 | G36: =(E36/C36)*100000 -> 0.86084089 | H36: =(G36-$H$4)/($H$3-$H$4) -> 0.13512462 | I36: =(H36*I$14)/H$14 -> 0.0094587235 | J36: =((G36-F36)/F36) -> 0.044987989 | K36: =(J36-$K$4)/($K$3-$K$4) -> 0.55293939 | L36: =(K36*$L$14)/$K$14 -> 0.016588182 | M36: =L36+I36 -> 0.026046905 | N36: 1824787088 | O36: 1952953912 | P36: =(O36-$P$4)/($P$3-$P$4) -> 0.22419749 | Q36: =(P36*$Q$15)/$P$15 -> 0.015693824 | R36: =(O36-N36)/N36 -> 0.070236591 | S36: =(R36-$S$4)/($S$3-$S$4) -> 0.48621744 | T36: =(S36*$T$27)/$S$27 -> 0.014586523 | U36: 1 | V36: 0.05 | W36: 68 | X36: =(W36/B36)*100000 -> 0.83607589 | Y36: =(X36-$Y$4)/($Y$3-$Y$4) -> 0.12672619 | Z36: =(Y36*$Z$14)/$Y$14 -> 0.0063363095 | AB36: =I36+L36+Q36+T36+V36+Z36 -> 0.11266356
A37: Yucatán | B37: 2420401 | C37: 2452378 | D37: 20 | E37: 23 | F37: =D37/B37*100000 -> 0.82630936 | G37: =(E37/C37)*100000 -> 0.93786521 | H37: =(G37-$H$4)/($H$3-$H$4) -> 0.14795285 | I37: =(H37*I$14)/H$14 -> 0.0103567 | J37: =((G37-F37)/F37) -> 0.13500494 | K37: =(J37-$K$4)/($K$3-$K$4) -> 0.60242487 | L37: =(K37*$L$14)/$K$14 -> 0.018072746 | M37: =L37+I37 -> 0.028429446 | N37: 638234032 | O37: 769882872 | P37: =(O37-$P$4)/($P$3-$P$4) -> 0.069066831 | Q37: =(P37*$Q$15)/$P$15 -> 0.0048346782 | R37: =(O37-N37)/N37 -> 0.20627048 | S37: =(R37-$S$4)/($S$3-$S$4) -> 0.71011492 | T37: =(S37*$T$27)/$S$27 -> 0.021303447 | U37: 0 | V37: 0 | W37: 35 | X37: =(W37/B37)*100000 -> 1.4460414 | Y37: =(X37-$Y$4)/($Y$3-$Y$4) -> 0.28474472 | Z37: =(Y37*$Z$14)/$Y$14 -> 0.014237236 | AB37: =I37+L37+Q37+T37+V37+Z37 -> 0.068804807
A38: Zacatecas | B38: 1667567 | C38: 1683013 | D38: 41 | E38: 42 | F38: =D38/B38*100000 -> 2.4586718 | G38: =(E38/C38)*100000 -> 2.4955244 | H38: =(G38-$H$4)/($H$3-$H$4) -> 0.40737759 | I38: =(H38*I$14)/H$14 -> 0.028516432 | J38: =((G38-F38)/F38) -> 0.014988812 | K38: =(J38-$K$4)/($K$3-$K$4) -> 0.53644778 | L38: =(K38*$L$14)/$K$14 -> 0.016093434 | M38: =L38+I38 -> 0.044609865 | N38: 578589829 | O38: 637124633 | P38: =(O38-$P$4)/($P$3-$P$4) -> 0.051658855 | Q38: =(P38*$Q$15)/$P$15 -> 0.0036161199 | R38: =(O38-N38)/N38 -> 0.10116805 | S38: =(R38-$S$4)/($S$3-$S$4) -> 0.53712737 | T38: =(S38*$T$27)/$S$27 -> 0.016113821 | U38: 0 | V38: 0 | W38: 35 | X38: =(W38/B38)*100000 -> 2.0988662 | Y38: =(X38-$Y$4)/($Y$3-$Y$4) -> 0.45386644 | Z38: =(Y38*$Z$14)/$Y$14 -> 0.022693322 | AB38: =I38+L38+Q38+T38+V38+Z38 -> 0.087033128
A39: Nacional | B39: =SUM(B4:B38) -> 129960600 | C39: =SUM(C4:C38) -> 131135337 | D39: =SUM(D4:D38) -> 1737 | E39: =SUM(E4:E38) -> 1600 | F39: =D39/B39*100000 -> 1.3365589 | G39: =(E39/C39)*100000 -> 1.2201135 | H39: =(G39-$H$4)/($H$3-$H$4) -> 0.1949607 | J39: =((G39-F39)/F39) -> -0.087123273 | N39: =SUM(N4:N38) -> 4.5839663e+10 | O39: =SUM(O4:O38) -> 4.9327832e+10 | U39: =SUM(U7:U38) -> 23 | W39: =SUM(W7:W38) -> 1951

Sheet Fiscalía
A1: Fuentes | E1: INEGI. Censo Nacional de Procuración de Justicia Estatal 2024. Tabulados básicos Personal de la Fiscalía General o Procuraduría General de Justicia, por nivel de gobierno, entidad federativa y tipo de unidad según cargo y sexo 2023 Suma de columnas K y L | M1: INEGI. Censo Nacional de Procuración de Justicia Estatal 2023. Tabulados básicos Presupuesto ejercido por la Fiscalía General o Procuraduría General de Justicia, por nivel de gobierno y entidad federativa según capítulo del Clasificador por Objeto del Gasto 2022 Columna D | N1: INEGI. Censo Nacional de Procuración de Justicia Estatal 2024. Tabulados básicos Presupuesto ejercido por la Fiscalía General o Procuraduría General de Justicia, por nivel de gobierno y entidad federativa 2023 Columna D | T1: INEGI. Censo Nacional de Procuración de Justicia Estatal 2024. Tabulados básicos Fiscalía General o Procuraduría General de Justicia, por nivel de gobierno y entidad federativa según condición de ejercicio de sus funciones como órgano constitucional autónomo 2023 Columna D | V1: INEGI. Censo Nacional de Procuración de Justicia Federal 2024. Tabulados básicos Unidades administrativas de la Fiscalía General o Procuraduría General de Justicia, por nivel de gobierno y entidad federativa según función administrativa principal 2023 Columna H | X1: INEGI. Censo Nacional de Procuración de Justicia Federal 2024. Tabulados básicos Unidades administrativas de la Fiscalía General o Procuraduría General de Justicia, por nivel de gobierno y entidad federativa según función administrativa principal 2023 Columna X | Z1: INEGI. Censo Nacional de Procuración de Justicia Federal 2024. Tabulados básicos Unidades administrativas de la Fiscalía General o Procuraduría General de Justicia, por nivel de gobierno y entidad federativa según función administrativa principal 2023 Columna AD | AB1: INEGI. Censo Nacional de Procuración de Justicia Federal 2024. Tabulados básicos Unidades administrativas de la Fiscalía General o Procuraduría General de Justicia, por nivel de gobierno y entidad federativa según función administrativa principal 2023 Columna K | AD1: INEGI. Censo Nacional de Procuración de Justicia Federal 2024. Tabulados básicos Unidades administrativas de la Fiscalía General o Procuraduría General de Justicia, por nivel de gobierno y entidad federativa según función administrativa principal 2023 Columna L | AF1: INEGI. Censo Nacional de Procuración de Justicia Federal 2024. Tabulados básicos Agencias y/o fiscalías del Ministerio Público de la Fiscalía General o Procuraduría General de Justicia, por nivel de gobierno y entidad federativa según tipo 2023 Columna D
G2: Val max | H2: =MAX(G6:G37) -> 36.446891 | J2: Val max | K2: =MAX(J6:J37) -> 0.84686454 | N2: Val max | O2: =MAX(N6:N37) -> 8366960210 | Q2: Val max | R2: =MAX(Q6:Q37) -> 0.24880847 | AG2: Val max | AH2: =MAX(AG6:AG37) -> 13.426441 | AI2: Valor más alto es el 5%, los demas son proporcionales
G3: Val min | H3: =MIN(G6:G37) -> 5.1773431 | I3: 0.07 | J3: Val min | K3: =MIN(J6:J37) -> -0.6037751 | L3: 0.03 | M3: Variación presupuestal (10%) | N3: Val min | O3: =MIN(N6:N37) -> 283901925 | P3: 0.07 | Q3: Val min | R3: =MIN(Q6:Q37) -> -0.052269805 | S3: 0.03 | U3: 0.05 | W3: 0.01 | Y3: 0.01 | AA3: 0.01 | AC3: 0.01 | AE3: 0.01 | AG3: Val min | AH3: =MIN(AG6:AG37) -> 0.35339535 | AI3: 0.05 | AK3: =I3+L3+P3+S3+U3+W3+Y3+AA3+AC3+AE3+AI3 -> 0.35
A4: Entidades / Variable | B4: Población 2022 | C4: Población 2023 | D4: Número de Fiscales 2022 | E4: Número de Fiscales 2023 | F4: Tasa operadores 2022 | G4: Tasa operadores 2023 | H4: Capacidad Fiscales 2023 normal | I4: Capacidad instalada | J4: Variación Operadores Fiscales | K4: Var Opr Fiscales Normal | L4: Variación Operadores Fiscales | M4: Presupuesto ejercido 2022 | N4: Presupuesto ejercido 2023 | O4: Presup inst normal Fiscalía | P4: Presupuesto instalado Fisc | Q4: Variación Presup Fiscal | R4: Var Presup Fisc Normal | S4: Variación Presup Fiscalía | T4: Autonomía consitucional (SI) | U4: Autonomía constitucional | V4: Asuntos internos | W4: Asuntos Internos | X4: MASC | Y4: MASC | Z4: UMECAS | AA4: UMECA | AB4: Mujeres | AC4: Atención especializada en justicia para las mujeres. | AD4: Adolescentes | AE4: Adolescentes | AF4: Agencias del MP 2023 | AG4: Agencias por 100,000 hab 2023 | AH4: Agencias por pob normal | AI4: Agencias por 100,000 hab 2023 | AK4: Total Fiscalías
A5: Federación
A6: Aguascalientes | B6: 1491126 | C6: 1510839 | D6: 165 | E6: 166 | F6: =D6/B6*100000 -> 11.065463 | G6: =E6/C6*100000 -> 10.987273 | H6: =(G6-$H$3)/($H$2-$H$3) -> 0.18580152 | I6: =(H6*$I$14)/$H$14 -> 0.013006106 | J6: =((G6-F6)/F6) -> -0.0070661882 | K6: =(J6-$K$3)/($K$2-$K$3) -> 0.41134193 | L6: =(K6*$L$14)/$K$14 -> 0.012340258 | M6: 5.6136427e+08 | N6: 626122684 | O6: =(N6-$O$3)/($O$2-$O$3) -> 0.042338029 | P6: =(O6*$P$14)/$O$14 -> 0.0029636621 | Q6: =(N6-M6)/M6 -> 0.11535899 | R6: =(Q6-$R$3)/($R$2-$R$3) -> 0.55676152 | S6: =(R6*$S$20)/$R$20 -> 0.016702845 | T6: 1 | U6: 0.05 | V6: 0 | W6: 0 | X6: 0 | Y6: 0 | Z6: 0 | AA6: 0 | AB6: 1 | AC6: 0.01 | AD6: 0 | AE6: 0 | AF6: 49 | AG6: =(AF6*100000)/B6 -> 3.2861073 | AH6: =(AG6-$AH$3)/($AH$2-$AH$3) -> 0.22433272 | AI6: =(AG6*AI$8)/AG$8 -> 0.01234797 | AK6: =I6+L6+P6+S6+U6+W6+Y6+AA6+AC6+AE6+AI6 -> 0.11736084
A7: Baja California | B7: 3948201 | C7: 4010510 | D7: 541 | E7: 527 | F7: =D7/B7*100000 -> 13.702443 | G7: =E7/C7*100000 -> 13.140473 | H7: =(G7-$H$3)/($H$2-$H$3) -> 0.25466087 | I7: =(H7*$I$14)/$H$14 -> 0.017826261 | J7: =((G7-F7)/F7) -> -0.04101238 | K7: =(J7-$K$3)/($K$2-$K$3) -> 0.38794109 | L7: =(K7*$L$14)/$K$14 -> 0.011638233 | M7: 2.1860695e+09 | N7: 2525012400 | O7: =(N7-$O$3)/($O$2-$O$3) -> 0.27726021 | P7: =(O7*$P$14)/$O$14 -> 0.019408215 | Q7: =(N7-M7)/M7 -> 0.15504674 | R7: =(Q7-$R$3)/($R$2-$R$3) -> 0.68858022 | S7: =(R7*$S$20)/$R$20 -> 0.020657407 | T7: 1 | U7: 0.05 | V7: 0 | W7: 0 | X7: 0 | Y7: 0 | Z7: 0 | AA7: 0 | AB7: 0 | AC7: 0 | AD7: 0 | AE7: 0 | AF7: 134 | AG7: =(AF7*100000)/B7 -> 3.3939508 | AH7: =(AG7-$AH$3)/($AH$2-$AH$3) -> 0.23258203 | AI7: =(AG7*AI$8)/AG$8 -> 0.012753206 | AK7: =I7+L7+P7+S7+U7+W7+Y7+AA7+AC7+AE7+AI7 -> 0.13228332
A8: Baja California Sur | B8: 849224 | C8: 867766 | D8: 142 | E8: 158 | F8: =D8/B8*100000 -> 16.721148 | G8: =E8/C8*100000 -> 18.207673 | H8: =(G8-$H$3)/($H$2-$H$3) -> 0.41670991 | I8: =(H8*$I$14)/$H$14 -> 0.029169693 | J8: =((G8-F8)/F8) -> 0.088900938 | K8: =(J8-$K$3)/($K$2-$K$3) -> 0.47749697 | L8: =(K8*$L$14)/$K$14 -> 0.014324909 | M8: 349915100 | N8: 417224055 | O8: =(N8-$O$3)/($O$2-$O$3) -> 0.016494021 | P8: =(O8*$P$14)/$O$14 -> 0.0011545814 | Q8: =(N8-M8)/M8 -> 0.19235796 | R8: =(Q8-$R$3)/($R$2-$R$3) -> 0.81250553 | S8: =(R8*$S$20)/$R$20 -> 0.024375166 | T8: 0 | U8: 0 | V8: 0 | W8: 0 | X8: 1 | Y8: 0.01 | Z8: 0 | AA8: 0 | AB8: 2 | AC8: 0.01 | AD8: 0 | AE8: 0 | AF8: 113 | AG8: =(AF8*100000)/B8 -> 13.306265 | AH8: =(AG8-$AH$3)/($AH$2-$AH$3) -> 0.99080738 | AI8: 0.05 | AK8: =I8+L8+P8+S8+U8+W8+Y8+AA8+AC8+AE8+AI8 -> 0.13902435
A9: Campeche | B9: 945445 | C9: 950291 | D9: 78 | E9: 127 | F9: =D9/B9*100000 -> 8.2500833 | G9: =E9/C9*100000 -> 13.364327 | H9: =(G9-$H$3)/($H$2-$H$3) -> 0.26181972 | I9: =(H9*$I$14)/$H$14 -> 0.01832738 | J9: =((G9-F9)/F9) -> 0.61990211 | K9: =(J9-$K$3)/($K$2-$K$3) -> 0.84354321 | L9: =(K9*$L$14)/$K$14 -> 0.025306296 | M9: 3.7776371e+08 | N9: 384950870 | O9: =(N9-$O$3)/($O$2-$O$3) -> 0.012501326 | P9: =(O9*$P$14)/$O$14 -> 0.00087509281 | Q9: =(N9-M9)/M9 -> 0.019025557 | R9: =(Q9-$R$3)/($R$2-$R$3) -> 0.23680008 | S9: =(R9*$S$20)/$R$20 -> 0.0071040025 | T9: 0 | U9: 0 | V9: 1 | W9: 0.01 | X9: 1 | Y9: 0.01 | Z9: 1 | AA9: 0.01 | AB9: 1 | AC9: 0.01 | AD9: 0 | AE9: 0 | AF9: 72 | AG9: =(AF9*100000)/B9 -> 7.6154615 | AH9: =(AG9-$AH$3)/($AH$2-$AH$3) -> 0.55549918 | AI9: =(AG9*AI$8)/AG$8 -> 0.028616074 | AK9: =I9+L9+P9+S9+U9+W9+Y9+AA9+AC9+AE9+AI9 -> 0.12022885
A10: Coahuila de Zaragoza | B10: 3273658 | C10: 3316738 | D10: 442 | E10: 396 | F10: =D10/B10*100000 -> 13.501716 | G10: =E10/C10*100000 -> 11.939442 | H10: =(G10-$H$3)/($H$2-$H$3) -> 0.21625188 | I10: =(H10*$I$14)/$H$14 -> 0.015137632 | J10: =((G10-F10)/F10) -> -0.1157093 | K10: =(J10-$K$3)/($K$2-$K$3) -> 0.33644868 | L10: =(K10*$L$14)/$K$14 -> 0.010093461 | M10: 8.8985211e+08 | N10: 921453667 | O10: =(N10-$O$3)/($O$2-$O$3) -> 0.078875064 | P10: =(O10*$P$14)/$O$14 -> 0.0055212545 | Q10: =(N10-M10)/M10 -> 0.035513272 | R10: =(Q10-$R$3)/($R$2-$R$3) -> 0.29156231 | S10: =(R10*$S$20)/$R$20 -> 0.0087468692 | T10: 1 | U10: 0.05 | V10: 0 | W10: 0 | X10: 2 | Y10: 0.01 | Z10: 0 | AA10: 0 | AB10: 0 | AC10: 0 | AD10: 0 | AE10: 0 | AF10: 331 | AG10: =(AF10*100000)/B10 -> 10.111013 | AH10: =(AG10-$AH$3)/($AH$2-$AH$3) -> 0.7463921 | AI10: =(AG10*AI$8)/AG$8 -> 0.03799343 | AK10: =I10+L10+P10+S10+U10+W10+Y10+AA10+AC10+AE10+AI10 -> 0.13749265
A11: Colima | B11: 752247 | C11: 757405 | D11: 138 | E11: 149 | F11: =D11/B11*100000 -> 18.345038 | G11: =E11/C11*100000 -> 19.672434 | H11: =(G11-$H$3)/($H$2-$H$3) -> 0.46355294 | I11: =(H11*$I$14)/$H$14 -> 0.032448706 | J11: =((G11-F11)/F11) -> 0.072357216 | K11: =(J11-$K$3)/($K$2-$K$3) -> 0.46609254 | L11: =(K11*$L$14)/$K$14 -> 0.013982776 | M11: 447888016 | N11: 462668320 | O11: =(N11-$O$3)/($O$2-$O$3) -> 0.022116183 | P11: =(O11*$P$14)/$O$14 -> 0.0015481328 | Q11: =(N11-M11)/M11 -> 0.032999999 | R11: =(Q11-$R$3)/($R$2-$R$3) -> 0.28321473 | S11: =(R11*$S$20)/$R$20 -> 0.008496442 | T11: 1 | U11: 0.05 | V11: 0 | W11: 0 | X11: 3 | Y11: 0.01 | Z11: 2 | AA11: 0.01 | AB11: 1 | AC11: 0.01 | AD11: 0 | AE11: 0 | AF11: 101 | AG11: =(AF11*100000)/B11 -> 13.426441 | AH11: =(AG11-$AH$3)/($AH$2-$AH$3) -> 1 | AI11: =(AG11*AI$8)/AG$8 -> 0.050451575 | AK11: =I11+L11+P11+S11+U11+W11+Y11+AA11+AC11+AE11+AI11 -> 0.18692763
A12: Chiapas | B12: 5862882 | C12: 5946352 | D12: 626 | E12: 532 | F12: =D12/B12*100000 -> 10.677343 | G12: =E12/C12*100000 -> 8.9466618 | H12: =(G12-$H$3)/($H$2-$H$3) -> 0.12054279 | I12: =(H12*$I$14)/$H$14 -> 0.0084379956 | J12: =((G12-F12)/F12) -> -0.1620891 | K12: =(J12-$K$3)/($K$2-$K$3) -> 0.30447672 | L12: =(K12*$L$14)/$K$14 -> 0.0091343015 | M12: 1.433471e+09 | N12: 1625451682 | O12: =(N12-$O$3)/($O$2-$O$3) -> 0.16597057 | P12: =(O12*$P$14)/$O$14 -> 0.01161794 | Q12: =(N12-M12)/M12 -> 0.13392716 | R12: =(Q12-$R$3)/($R$2-$R$3) -> 0.61843373 | S12: =(R12*$S$20)/$R$20 -> 0.018553012 | T12: 1 | U12: 0.05 | V12: 0 | W12: 0 | X12: 0 | Y12: 0 | Z12: 0 | AA12: 0 | AB12: 1 | AC12: 0.01 | AD12: 0 | AE12: 0 | AF12: 112 | AG12: =(AF12*100000)/B12 -> 1.9103233 | AH12: =(AG12-$AH$3)/($AH$2-$AH$3) -> 0.11909451 | AI12: =(AG12*AI$8)/AG$8 -> 0.0071782849 | AK12: =I12+L12+P12+S12+U12+W12+Y12+AA12+AC12+AE12+AI12 -> 0.11492153
A13: Chihuahua | B13: 3898274 | C13: 3947936 | D13: 1247 | E13: 1072 | F13: =D13/B13*100000 -> 31.988516 | G13: =E13/C13*100000 -> 27.153429 | H13: =(G13-$H$3)/($H$2-$H$3) -> 0.70279513 | I13: =(H13*$I$14)/$H$14 -> 0.049195659 | J13: =((G13-F13)/F13) -> -0.15115071 | K13: =(J13-$K$3)/($K$2-$K$3) -> 0.31201711 | L13: =(K13*$L$14)/$K$14 -> 0.0093605133 | M13: 2723844653 | N13: 2973179136 | O13: =(N13-$O$3)/($O$2-$O$3) -> 0.33270541 | P13: =(O13*$P$14)/$O$14 -> 0.023289379 | Q13: =(N13-M13)/M13 -> 0.091537703 | R13: =(Q13-$R$3)/($R$2-$R$3) -> 0.47764159 | S13: =(R13*$S$20)/$R$20 -> 0.014329248 | T13: 0 | U13: 0 | V13: 1 | W13: 0.01 | X13: 11 | Y13: 0.01 | Z13: 0 | AA13: 0 | AB13: 2 | AC13: 0.01 | AD13: 0 | AE13: 0 | AF13: 180 | AG13: =(AF13*100000)/B13 -> 4.6174281 | AH13: =(AG13-$AH$3)/($AH$2-$AH$3) -> 0.32616981 | AI13: =(AG13*AI$8)/AG$8 -> 0.017350579 | AK13: =I13+L13+P13+S13+U13+W13+Y13+AA13+AC13+AE13+AI13 -> 0.14352538
A14: Ciudad de México | B14: 9237644 | C14: 9221637 | D14: 1823 | E14: 3361 | F14: =D14/B14*100000 -> 19.734469 | G14: =E14/C14*100000 -> 36.446891 | H14: =(G14-$H$3)/($H$2-$H$3) -> 1 | I14: 0.07 | J14: =((G14-F14)/F14) -> 0.84686454 | K14: =(J14-$K$3)/($K$2-$K$3) -> 1 | L14: 0.03 | M14: 7.4685e+09 | N14: 8366960210 | O14: =(N14-$O$3)/($O$2-$O$3) -> 1 | P14: 0.07 | Q14: =(N14-M14)/M14 -> 0.12029995 | R14: =(Q14-$R$3)/($R$2-$R$3) -> 0.5731724 | S14: =(R14*$S$20)/$R$20 -> 0.017195172 | T14: 1 | U14: 0.05 | V14: 1 | W14: 0.01 | X14: 0 | Y14: 0 | Z14: 1 | AA14: 0.01 | AB14: 1 | AC14: 0.01 | AD14: 0 | AE14: 0 | AF14: 48 | AG14: =(AF14*100000)/B14 -> 0.51961301 | AH14: =(AG14-$AH$3)/($AH$2-$AH$3) -> 0.012714532 | AI14: =(AG14*AI$8)/AG$8 -> 0.0019525126 | AK14: =I14+L14+P14+S14+U14+W14+Y14+AA14+AC14+AE14+AI14 -> 0.26914768
A15: Durango | B15: 1884286 | C15: 1899457 | D15: 218 | E15: 218 | F15: =D15/B15*100000 -> 11.569369 | G15: =E15/C15*100000 -> 11.476964 | H15: =(G15-$H$3)/($H$2-$H$3) -> 0.20146185 | I15: =(H15*$I$14)/$H$14 -> 0.01410233 | J15: =((G15-F15)/F15) -> -0.0079870194 | K15: =(J15-$K$3)/($K$2-$K$3) -> 0.41070716 | L15: =(K15*$L$14)/$K$14 -> 0.012321215 | M15: 5.9955279e+08 | N15: 616514291 | O15: =(N15-$O$3)/($O$2-$O$3) -> 0.041149322 | P15: =(O15*$P$14)/$O$14 -> 0.0028804525 | Q15: =(N15-M15)/M15 -> 0.028290257 | R15: =(Q15-$R$3)/($R$2-$R$3) -> 0.26757182 | S15: =(R15*$S$20)/$R$20 -> 0.0080271545 | T15: 0 | U15: 0 | V15: 1 | W15: 0.01 | X15: 1 | Y15: 0.01 | Z15: 0 | AA15: 0 | AB15: 1 | AC15: 0.01 | AD15: 1 | AE15: 0.01 | AF15: 44 | AG15: =(AF15*100000)/B15 -> 2.335102 | AH15: =(AG15-$AH$3)/($AH$2-$AH$3) -> 0.15158722 | AI15: =(AG15*AI$8)/AG$8 -> 0.0087744454 | AK15: =I15+L15+P15+S15+U15+W15+Y15+AA15+AC15+AE15+AI15 -> 0.086105597
A16: Guanajuato | B16: 6360814 | C16: 6422483 | D16: 521 | E16: 561 | F16: =D16/B16*100000 -> 8.1907756 | G16: =E16/C16*100000 -> 8.7349394 | H16: =(G16-$H$3)/($H$2-$H$3) -> 0.11377192 | I16: =(H16*$I$14)/$H$14 -> 0.0079640341 | J16: =((G16-F16)/F16) -> 0.066436181 | K16: =(J16-$K$3)/($K$2-$K$3) -> 0.46201087 | L16: =(K16*$L$14)/$K$14 -> 0.013860326 | M16: 3.562021e+09 | N16: 4213231927 | O16: =(N16-$O$3)/($O$2-$O$3) -> 0.48611922 | P16: =(O16*$P$14)/$O$14 -> 0.034028346 | Q16: =(N16-M16)/M16 -> 0.18282064 | R16: =(Q16-$R$3)/($R$2-$R$3) -> 0.78082833 | S16: =(R16*$S$20)/$R$20 -> 0.02342485 | T16: 1 | U16: 0.05 | V16: 0 | W16: 0 | X16: 0 | Y16: 0 | Z16: 0 | AA16: 0 | AB16: 1 | AC16: 0.01 | AD16: 0 | AE16: 0 | AF16: 319 | AG16: =(AF16*100000)/B16 -> 5.0150814 | AH16: =(AG16-$AH$3)/($AH$2-$AH$3) -> 0.3565876 | AI16: =(AG16*AI$8)/AG$8 -> 0.018844812 | AK16: =I16+L16+P16+S16+U16+W16+Y16+AA16+AC16+AE16+AI16 -> 0.15812237
A17: Guerrero | B17: 3599951 | C17: 3604215 | D17: 484 | E17: 192 | F17: =D17/B17*100000 -> 13.444627 | G17: =E17/C17*100000 -> 5.3270962 | H17: =(G17-$H$3)/($H$2-$H$3) -> 0.0047891044 | I17: =(H17*$I$14)/$H$14 -> 0.00033523731 | J17: =((G17-F17)/F17) -> -0.6037751 | K17: =(J17-$K$3)/($K$2-$K$3) -> 0 | L17: =(K17*$L$14)/$K$14 -> 0 | M17: 1500808920 | N17: 1495237985 | O17: =(N17-$O$3)/($O$2-$O$3) -> 0.14986111 | P17: =(O17*$P$14)/$O$14 -> 0.010490277 | Q17: =(N17-M17)/M17 -> -0.0037119549 | R17: =(Q17-$R$3)/($R$2-$R$3) -> 0.16127982 | S17: =(R17*$S$20)/$R$20 -> 0.0048383946 | T17: 1 | U17: 0.05 | V17: 0 | W17: 0 | X17: 1 | Y17: 0.01 | Z17: 0 | AA17: 0 | AB17: 1 | AC17: 0.01 | AD17: 0 | AE17: 0 | AF17: 81 | AG17: =(AF17*100000)/B17 -> 2.2500306 | AH17: =(AG17-$AH$3)/($AH$2-$AH$3) -> 0.14507983 | AI17: =(AG17*AI$8)/AG$8 -> 0.0084547788 | AK17: =I17+L17+P17+S17+U17+W17+Y17+AA17+AC17+AE17+AI17 -> 0.094118688
A18: Hidalgo | B18: 3190331 | C18: 3227801 | D18: 351 | E18: 407 | F18: =D18/B18*100000 -> 11.001993 | G18: =E18/C18*100000 -> 12.609204 | H18: =(G18-$H$3)/($H$2-$H$3) -> 0.23767086 | I18: =(H18*$I$14)/$H$14 -> 0.016636961 | J18: =((G18-F18)/F18) -> 0.14608357 | K18: =(J18-$K$3)/($K$2-$K$3) -> 0.51691588 | L18: =(K18*$L$14)/$K$14 -> 0.015507476 | M18: 775647562 | N18: 810316193 | O18: =(N18-$O$3)/($O$2-$O$3) -> 0.065125631 | P18: =(O18*$P$14)/$O$14 -> 0.0045587941 | Q18: =(N18-M18)/M18 -> 0.044696371 | R18: =(Q18-$R$3)/($R$2-$R$3) -> 0.32206301 | S18: =(R18*$S$20)/$R$20 -> 0.0096618902 | T18: 0 | U18: 0 | V18: 0 | W18: 0 | X18: 0 | Y18: 0 | Z18: 0 | AA18: 0 | AB18: 0 | AC18: 0 | AD18: 0 | AE18: 0 | AF18: 55 | AG18: =(AF18*100000)/B18 -> 1.7239591 | AH18: =(AG18-$AH$3)/($AH$2-$AH$3) -> 0.1048389 | AI18: =(AG18*AI$8)/AG$8 -> 0.0064779973 | AK18: =I18+L18+P18+S18+U18+W18+Y18+AA18+AC18+AE18+AI18 -> 0.052843119
A19: Jalisco | B19: 8647986 | C19: 8735511 | D19: 777 | E19: 798 | F19: =D19/B19*100000 -> 8.9847509 | G19: =E19/C19*100000 -> 9.1351267 | H19: =(G19-$H$3)/($H$2-$H$3) -> 0.1265699 | I19: =(H19*$I$14)/$H$14 -> 0.0088598932 | J19: =((G19-F19)/F19) -> 0.016736783 | K19: =(J19-$K$3)/($K$2-$K$3) -> 0.42775054 | L19: =(K19*$L$14)/$K$14 -> 0.012832516 | M19: 2549142131 | N19: 2705934680 | O19: =(N19-$O$3)/($O$2-$O$3) -> 0.29964311 | P19: =(O19*$P$14)/$O$14 -> 0.020975018 | Q19: =(N19-M19)/M19 -> 0.061507967 | R19: =(Q19-$R$3)/($R$2-$R$3) -> 0.37790097 | S19: =(R19*$S$20)/$R$20 -> 0.011337029 | T19: 0 | U19: 0 | V19: 1 | W19: 0.01 | X19: 1 | Y19: 0.01 | Z19: 1 | AA19: 0.01 | AB19: 0 | AC19: 0 | AD19: 0 | AE19: 0 | AF19: 463 | AG19: =(AF19*100000)/B19 -> 5.3538477 | AH19: =(AG19-$AH$3)/($AH$2-$AH$3) -> 0.38250095 | AI19: =(AG19*AI$8)/AG$8 -> 0.02011777 | AK19: =I19+L19+P19+S19+U19+W19+Y19+AA19+AC19+AE19+AI19 -> 0.10412223
A20: México | B20: 17379644 | C20: 17501220 | D20: 1394 | E20: 1345 | F20: =D20/B20*100000 -> 8.0208778 | G20: =E20/C20*100000 -> 7.6851785 | H20: =(G20-$H$3)/($H$2-$H$3) -> 0.080200566 | I20: =(H20*$I$14)/$H$14 -> 0.0056140396 | J20: =((G20-F20)/F20) -> -0.04185318 | K20: =(J20-$K$3)/($K$2-$K$3) -> 0.38736148 | L20: =(K20*$L$14)/$K$14 -> 0.011620844 | M20: 4.2582243e+09 | N20: 5317706601 | O20: =(N20-$O$3)/($O$2-$O$3) -> 0.62275991 | P20: =(O20*$P$14)/$O$14 -> 0.043593194 | Q20: =(N20-M20)/M20 -> 0.24880847 | R20: =(Q20-$R$3)/($R$2-$R$3) -> 1 | S20: 0.03 | T20: 1 | U20: 0.05 | V20: 0 | W20: 0 | X20: 1 | Y20: 0.01 | Z20: 2 | AA20: 0.01 | AB20: 0 | AC20: 0 | AD20: 1 | AE20: 0.01 | AF20: 145 | AG20: =(AF20*100000)/B20 -> 0.83430938 | AH20: =(AG20-$AH$3)/($AH$2-$AH$3) -> 0.036786686 | AI20: =(AG20*AI$8)/AG$8 -> 0.0031350246 | AK20: =I20+L20+P20+S20+U20+W20+Y20+AA20+AC20+AE20+AI20 -> 0.1739631
A21: Michoacán de Ocampo | B21: 4901506 | C21: 4950601 | D21: 571 | E21: 575 | F21: =D21/B21*100000 -> 11.649481 | G21: =E21/C21*100000 -> 11.614751 | H21: =(G21-$H$3)/($H$2-$H$3) -> 0.20586829 | I21: =(H21*$I$14)/$H$14 -> 0.01441078 | J21: =((G21-F21)/F21) -> -0.0029811948 | K21: =(J21-$K$3)/($K$2-$K$3) -> 0.41415793 | L21: =(K21*$L$14)/$K$14 -> 0.012424738 | M21: 1.4842492e+09 | N21: 1623467337 | O21: =(N21-$O$3)/($O$2-$O$3) -> 0.16572507 | P21: =(O21*$P$14)/$O$14 -> 0.011600755 | Q21: =(N21-M21)/M21 -> 0.09379704 | R21: =(Q21-$R$3)/($R$2-$R$3) -> 0.48514574 | S21: =(R21*$S$20)/$R$20 -> 0.014554372 | T21: 1 | U21: 0.05 | V21: 1 | W21: 0.01 | X21: 1 | Y21: 0.01 | Z21: 0 | AA21: 0 | AB21: 1 | AC21: 0.01 | AD21: 0 | AE21: 0 | AF21: 115 | AG21: =(AF21*100000)/B21 -> 2.3462177 | AH21: =(AG21-$AH$3)/($AH$2-$AH$3) -> 0.15243749 | AI21: =(AG21*AI$8)/AG$8 -> 0.008816214 | AK21: =I21+L21+P21+S21+U21+W21+Y21+AA21+AC21+AE21+AI21 -> 0.14180686
A22: Morelos | B22: 2017078 | C22: 2030857 | D22: 255 | E22: 242 | F22: =D22/B22*100000 -> 12.64205 | G22: =E22/C22*100000 -> 11.916152 | H22: =(G22-$H$3)/($H$2-$H$3) -> 0.21550707 | I22: =(H22*$I$14)/$H$14 -> 0.015085495 | J22: =((G22-F22)/F22) -> -0.05741932 | K22: =(J22-$K$3)/($K$2-$K$3) -> 0.37663095 | L22: =(K22*$L$14)/$K$14 -> 0.011298928 | M22: 7.3050875e+08 | N22: 890917049 | O22: =(N22-$O$3)/($O$2-$O$3) -> 0.07509721 | P22: =(O22*$P$14)/$O$14 -> 0.0052568047 | Q22: =(N22-M22)/M22 -> 0.21958436 | R22: =(Q22-$R$3)/($R$2-$R$3) -> 0.90293518 | S22: =(R22*$S$20)/$R$20 -> 0.027088056 | T22: 1 | U22: 0.05 | V22: 0 | W22: 0 | X22: 1 | Y22: 0.01 | Z22: 0 | AA22: 0 | AB22: 0 | AC22: 0 | AD22: 0 | AE22: 0 | AF22: 79 | AG22: =(AF22*100000)/B22 -> 3.9165565 | AH22: =(AG22-$AH$3)/($AH$2-$AH$3) -> 0.27255785 | AI22: =(AG22*AI$8)/AG$8 -> 0.014716964 | AK22: =I22+L22+P22+S22+U22+W22+Y22+AA22+AC22+AE22+AI22 -> 0.13344625
A23: Nayarit | B23: 1278605 | C23: 1294124 | D23: 200 | E23: 198 | F23: =D23/B23*100000 -> 15.642047 | G23: =E23/C23*100000 -> 15.299925 | H23: =(G23-$H$3)/($H$2-$H$3) -> 0.32372012 | I23: =(H23*$I$14)/$H$14 -> 0.022660408 | J23: =((G23-F23)/F23) -> -0.021871977 | K23: =(J23-$K$3)/($K$2-$K$3) -> 0.40113554 | L23: =(K23*$L$14)/$K$14 -> 0.012034066 | M23: 5.914146e+08 | N23: 702819082 | O23: =(N23-$O$3)/($O$2-$O$3) -> 0.051826566 | P23: =(O23*$P$14)/$O$14 -> 0.0036278596 | Q23: =(N23-M23)/M23 -> 0.18836951 | R23: =(Q23-$R$3)/($R$2-$R$3) -> 0.79925831 | S23: =(R23*$S$20)/$R$20 -> 0.023977749 | T23: 1 | U23: 0.05 | V23: 1 | W23: 0.01 | X23: 0 | Y23: 0 | Z23: 0 | AA23: 0 | AB23: 1 | AC23: 0.01 | AD23: 0 | AE23: 0 | AF23: 81 | AG23: =(AF23*100000)/B23 -> 6.3350292 | AH23: =(AG23-$AH$3)/($AH$2-$AH$3) -> 0.45755473 | AI23: =(AG23*AI$8)/AG$8 -> 0.023804685 | AK23: =I23+L23+P23+S23+U23+W23+Y23+AA23+AC23+AE23+AI23 -> 0.15610477
A24: Nuevo León | B24: 6095498 | C24: 6202153 | D24: 628 | E24: 608 | F24: =D24/B24*100000 -> 10.302686 | G24: =E24/C24*100000 -> 9.8030474 | H24: =(G24-$H$3)/($H$2-$H$3) -> 0.14793 | I24: =(H24*$I$14)/$H$14 -> 0.0103551 | J24: =((G24-F24)/F24) -> -0.048495924 | K24: =(J24-$K$3)/($K$2-$K$3) -> 0.3827823 | L24: =(K24*$L$14)/$K$14 -> 0.011483469 | M24: 3747142255 | N24: 3947142255 | O24: =(N24-$O$3)/($O$2-$O$3) -> 0.45319979 | P24: =(O24*$P$14)/$O$14 -> 0.031723985 | Q24: =(N24-M24)/M24 -> 0.053374008 | R24: =(Q24-$R$3)/($R$2-$R$3) -> 0.35088487 | S24: =(R24*$S$20)/$R$20 -> 0.010526546 | T24: 1 | U24: 0.05 | V24: 3 | W24: 0.01 | X24: 1 | Y24: 0.01 | Z24: 0 | AA24: 0 | AB24: 1 | AC24: 0.01 | AD24: 1 | AE24: 0.01 | AF24: 72 | AG24: =(AF24*100000)/B24 -> 1.1811996 | AH24: =(AG24-$AH$3)/($AH$2-$AH$3) -> 0.063321455 | AI24: =(AG24*AI$8)/AG$8 -> 0.0044385092 | AK24: =I24+L24+P24+S24+U24+W24+Y24+AA24+AC24+AE24+AI24 -> 0.15852761
A25: Oaxaca | B25: 4244538 | C25: 4276769 | D25: 445 | E25: 448 | F25: =D25/B25*100000 -> 10.484062 | G25: =E25/C25*100000 -> 10.475198 | H25: =(G25-$H$3)/($H$2-$H$3) -> 0.16942536 | I25: =(H25*$I$14)/$H$14 -> 0.011859775 | J25: =((G25-F25)/F25) -> -0.00084553014 | K25: =(J25-$K$3)/($K$2-$K$3) -> 0.41563015 | L25: =(K25*$L$14)/$K$14 -> 0.012468904 | M25: 8.3070275e+08 | N25: 897759188 | O25: =(N25-$O$3)/($O$2-$O$3) -> 0.075943689 | P25: =(O25*$P$14)/$O$14 -> 0.0053160582 | Q25: =(N25-M25)/M25 -> 0.080722547 | R25: =(Q25-$R$3)/($R$2-$R$3) -> 0.44172018 | S25: =(R25*$S$20)/$R$20 -> 0.013251606 | T25: 1 | U25: 0.05 | V25: 0 | W25: 0 | X25: 1 | Y25: 0.01 | Z25: 0 | AA25: 0 | AB25: 3 | AC25: 0.01 | AD25: 1 | AE25: 0.01 | AF25: 15 | AG25: =(AF25*100000)/B25 -> 0.35339535 | AH25: =(AG25-$AH$3)/($AH$2-$AH$3) -> 0 | AI25: =(AG25*AI$8)/AG$8 -> 0.0013279284 | AK25: =I25+L25+P25+S25+U25+W25+Y25+AA25+AC25+AE25+AI25 -> 0.12422427
A26: Puebla | B26: 6824785 | C26: 6907421 | D26: 666 | E26: 666 | F26: =D26/B26*100000 -> 9.7585492 | G26: =E26/C26*100000 -> 9.6418041 | H26: =(G26-$H$3)/($H$2-$H$3) -> 0.14277344 | I26: =(H26*$I$14)/$H$14 -> 0.009994141 | J26: =((G26-F26)/F26) -> -0.011963365 | K26: =(J26-$K$3)/($K$2-$K$3) -> 0.40796606 | L26: =(K26*$L$14)/$K$14 -> 0.012238982 | M26: 1.4844638e+09 | N26: 1559690398 | O26: =(N26-$O$3)/($O$2-$O$3) -> 0.15783487 | P26: =(O26*$P$14)/$O$14 -> 0.011048441 | Q26: =(N26-M26)/M26 -> 0.05067593 | R26: =(Q26-$R$3)/($R$2-$R$3) -> 0.34192349 | S26: =(R26*$S$20)/$R$20 -> 0.010257705 | T26: 1 | U26: 0.05 | V26: 1 | W26: 0.01 | X26: 1 | Y26: 0.01 | Z26: 0 | AA26: 0 | AB26: 0 | AC26: 0 | AD26: 0 | AE26: 0 | AF26: 235 | AG26: =(AF26*100000)/B26 -> 3.4433319 | AH26: =(AG26-$AH$3)/($AH$2-$AH$3) -> 0.23635935 | AI26: =(AG26*AI$8)/AG$8 -> 0.012938762 | AK26: =I26+L26+P26+S26+U26+W26+Y26+AA26+AC26+AE26+AI26 -> 0.12647803
A27: Querétaro | B27: 2508214 | C27: 2557915 | D27: 214 | E27: 181 | F27: =D27/B27*100000 -> 8.5319674 | G27: =E27/C27*100000 -> 7.0760756 | H27: =(G27-$H$3)/($H$2-$H$3) -> 0.060721459 | I27: =(H27*$I$14)/$H$14 -> 0.0042505021 | J27: =((G27-F27)/F27) -> -0.17063963 | K27: =(J27-$K$3)/($K$2-$K$3) -> 0.2985824 | L27: =(K27*$L$14)/$K$14 -> 0.0089574721 | M27: 1007238043 | N27: 1186608362 | O27: =(N27-$O$3)/($O$2-$O$3) -> 0.11167882 | P27: =(O27*$P$14)/$O$14 -> 0.0078175176 | Q27: =(N27-M27)/M27 -> 0.17808136 | R27: =(Q27-$R$3)/($R$2-$R$3) -> 0.76508729 | S27: =(R27*$S$20)/$R$20 -> 0.022952619 | T27: 1 | U27: 0.05 | V27: 0 | W27: 0 | X27: 0 | Y27: 0 | Z27: 0 | AA27: 0 | AB27: 0 | AC27: 0 | AD27: 0 | AE27: 0 | AF27: 44 | AG27: =(AF27*100000)/B27 -> 1.7542363 | AH27: =(AG27-$AH$3)/($AH$2-$AH$3) -> 0.1071549 | AI27: =(AG27*AI$8)/AG$8 -> 0.0065917679 | AK27: =I27+L27+P27+S27+U27+W27+Y27+AA27+AC27+AE27+AI27 -> 0.10056988
